<?xml version="1.0" encoding="utf-8"?>
<robot xmlns:xacro="http://www.ros.org/wiki/xacro" name="prismatic_xyz_revolute_z">
  <xacro:macro name="prismatic_xyz_revolute_z" params="connected_to:='' ns:='' rpy:='0 0 0' xyz:='0 0 0' ">
    <xacro:unless value="${connected_to == ''}">
      <joint name="${ns}_base_joint" type="fixed">
        <parent link="${connected_to}"/>
        <child link="${ns}_base_link"/>
        <origin xyz="${xyz}" rpy="${rpy}"/>
      </joint>
    </xacro:unless>
    <link name="${ns}_base_link" />
    <link name="${ns}_prismatic_x_link" />
    <link name="${ns}_prismatic_y_link" />
    <link name="${ns}_prismatic_z_link" />
    <link name="${ns}_revolute_z_link" />
    <joint name="${ns}_prismatic_x_joint" type="prismatic">
      <parent link="${ns}_base_link"/>
      <child link="${ns}_prismatic_x_link"/>
      <origin xyz="0 0 0" rpy="0 0 0"/>
      <axis xyz="1 0 0"/>
    </joint>
    <joint name="${ns}_prismatic_y_joint" type="prismatic">
      <parent link="${ns}_prismatic_x_link"/>
      <child link="${ns}_prismatic_y_link"/>
      <origin xyz="0 0 0" rpy="0 0 0"/>
      <axis xyz="0 1 0"/>
    </joint>
    <joint name="${ns}_prismatic_z_joint" type="prismatic">
      <parent link="${ns}_prismatic_y_link"/>
      <child link="${ns}_prismatic_z_link"/>
      <origin xyz="0 0 0" rpy="0 0 0"/>
      <axis xyz="0 0 1"/>
    </joint>
    <joint name="${ns}_revolute_z_joint" type="revolute">
      <parent link="${ns}_prismatic_z_link"/>
      <child link="${ns}_revolute_z_link"/>
      <origin xyz="0 0 0" rpy="0 0 0"/>
      <axis xyz="0 0 -1"/>
    </joint>
  </xacro:macro>
</robot>
