<?xml version="1.0" ?>
<!-- =================================================================================== -->
<!-- |    This document was autogenerated by xacro from hand_fingers_fixed_prismatic_xyz_revolute_z.urdf.xacro | -->
<!-- |    EDITING THIS FILE BY HAND IS NOT RECOMMENDED                                 | -->
<!-- =================================================================================== -->
<robot name="ff_pxyz_rz" xmlns:xacro="http://www.ros.org/wiki/xacro">
  <material name="redtran">
    <color rgba=".9 .1 .1 0.3"/>
  </material>
  <material name="greentran">
    <color rgba=".1 .9 .1 0.3"/>
  </material>
  <material name="bluetran">
    <color rgba=".1 .1 .9 0.3"/>
  </material>
  <link name="pxyz_rz_base_link"/>
  <link name="pxyz_rz_prismatic_x_link"/>
  <link name="pxyz_rz_prismatic_y_link"/>
  <link name="pxyz_rz_prismatic_z_link"/>
  <link name="pxyz_rz_revolute_z_link"/>
  <joint name="pxyz_rz_prismatic_x_joint" type="prismatic">
    <parent link="pxyz_rz_base_link"/>
    <child link="pxyz_rz_prismatic_x_link"/>
    <origin rpy="0 0 0" xyz="0 0 0"/>
    <axis xyz="1 0 0"/>
  </joint>
  <joint name="pxyz_rz_prismatic_y_joint" type="prismatic">
    <parent link="pxyz_rz_prismatic_x_link"/>
    <child link="pxyz_rz_prismatic_y_link"/>
    <origin rpy="0 0 0" xyz="0 0 0"/>
    <axis xyz="0 1 0"/>
  </joint>
  <joint name="pxyz_rz_prismatic_z_joint" type="prismatic">
    <parent link="pxyz_rz_prismatic_y_link"/>
    <child link="pxyz_rz_prismatic_z_link"/>
    <origin rpy="0 0 0" xyz="0 0 0"/>
    <axis xyz="0 0 1"/>
  </joint>
  <joint name="pxyz_rz_revolute_z_joint" type="revolute">
    <parent link="pxyz_rz_prismatic_z_link"/>
    <child link="pxyz_rz_revolute_z_link"/>
    <origin rpy="0 0 0" xyz="0 0 0"/>
    <axis xyz="0 0 -1"/>
  </joint>
  <joint name="panda_hand_joint" type="fixed">
    <parent link="pxyz_rz_revolute_z_link"/>
    <child link="panda_hand"/>
    <origin rpy="3.14159265359 0 0" xyz="0 0 0"/>
  </joint>
  <link name="panda_hand">
    <visual>
      <geometry>
        <mesh filename="package://franka_description/meshes/visual/hand.dae"/>
      </geometry>
    </visual>
    <visual>
      <origin xyz="0 -.077 .041"/>
      <geometry>
        <sphere radius="0.033"/>
      </geometry>
      <material name="redtran"/>
    </visual>
    <visual>
      <origin xyz="0 .075 .012"/>
      <geometry>
        <sphere radius="0.033"/>
      </geometry>
      <material name="redtran"/>
    </visual>
    <visual>
      <origin xyz="0 .077 .041"/>
      <geometry>
        <sphere radius="0.033"/>
      </geometry>
      <material name="redtran"/>
    </visual>
    <visual>
      <origin xyz="0 -.05 .002"/>
      <geometry>
        <sphere radius="0.033"/>
      </geometry>
      <material name="redtran"/>
    </visual>
    <visual>
      <origin xyz="0 -.046 .041"/>
      <geometry>
        <sphere radius="0.033"/>
      </geometry>
      <material name="redtran"/>
    </visual>
    <visual>
      <origin xyz="0 .046 .041"/>
      <geometry>
        <sphere radius="0.033"/>
      </geometry>
      <material name="redtran"/>
    </visual>
    <visual>
      <origin xyz="0 .016 .041"/>
      <geometry>
        <sphere radius="0.033"/>
      </geometry>
      <material name="redtran"/>
    </visual>
    <visual>
      <origin xyz="0 -.016 .041"/>
      <geometry>
        <sphere radius="0.033"/>
      </geometry>
      <material name="redtran"/>
    </visual>
    <visual>
      <origin xyz="0 -.075 .002"/>
      <geometry>
        <sphere radius="0.033"/>
      </geometry>
      <material name="redtran"/>
    </visual>
    <visual>
      <origin xyz="0 .051 .003"/>
      <geometry>
        <sphere radius="0.033"/>
      </geometry>
      <material name="redtran"/>
    </visual>
    <visual>
      <origin xyz="0 0 .003"/>
      <geometry>
        <sphere radius="0.033"/>
      </geometry>
      <material name="redtran"/>
    </visual>
  </link>
  <link name="panda_leftfinger">
    <visual>
      <geometry>
        <mesh filename="package://franka_description/meshes/visual/finger.dae"/>
      </geometry>
    </visual>
    <visual>
      <origin xyz="0 .014 .022"/>
      <geometry>
        <sphere radius="0.017"/>
      </geometry>
      <material name="greentran"/>
    </visual>
    <visual>
      <origin xyz="0 .015 .005"/>
      <geometry>
        <sphere radius="0.018"/>
      </geometry>
      <material name="greentran"/>
    </visual>
    <visual>
      <origin xyz="0 .008 .044"/>
      <geometry>
        <sphere radius="0.014"/>
      </geometry>
      <material name="greentran"/>
    </visual>
  </link>
  <link name="panda_rightfinger">
    <visual>
      <origin rpy="0 0 3.14159265359" xyz="0 0 0"/>
      <geometry>
        <mesh filename="package://franka_description/meshes/visual/finger.dae"/>
      </geometry>
    </visual>
    <visual>
      <origin xyz="0 -.014 .022"/>
      <geometry>
        <sphere radius="0.017"/>
      </geometry>
      <material name="greentran"/>
    </visual>
    <visual>
      <origin xyz="0 -.015 .005"/>
      <geometry>
        <sphere radius="0.018"/>
      </geometry>
      <material name="greentran"/>
    </visual>
    <visual>
      <origin xyz="0 -.008 .044"/>
      <geometry>
        <sphere radius="0.014"/>
      </geometry>
      <material name="greentran"/>
    </visual>
  </link>
  <link name="panda_hand_center">
    <visual>
      <origin xyz="0 0 0"/>
      <geometry>
        <sphere radius="0.02"/>
      </geometry>
      <material name="bluetran"/>
    </visual>
  </link>
  <joint name="panda_finger_joint1" type="fixed">
    <parent link="panda_hand"/>
    <child link="panda_leftfinger"/>
    <origin rpy="0 0 0" xyz="0 0.02 0.0584"/>
  </joint>
  <joint name="panda_finger_joint2" type="fixed">
    <parent link="panda_hand"/>
    <child link="panda_rightfinger"/>
    <origin rpy="0 0 0" xyz="0 -0.02 0.0584"/>
    <mimic joint="panda_finger_joint1"/>
  </joint>
  <joint name="panda_hand_center_joint" type="fixed">
    <parent link="panda_hand"/>
    <child link="panda_hand_center"/>
    <origin rpy="0 0 0" xyz="0 0 0.08"/>
  </joint>
</robot>

