<?xml version="1.0" ?>
<!-- =================================================================================== -->
<!-- |    This document was autogenerated by xacro from panda_arm.urdf.xacro           | -->
<!-- |    EDITING THIS FILE BY HAND IS NOT RECOMMENDED                                 | -->
<!-- =================================================================================== -->
<robot name="panda" xmlns:xacro="http://www.ros.org/wiki/xacro">
  <link name="world"/>
  <joint name="panda_joint_world" type="fixed">
    <parent link="world"/>
    <child link="panda_link0"/>
    <origin rpy="0 0 0" xyz="0 0 0"/>
  </joint>
  <gazebo>
    <plugin filename="libgazebo_ros_control.so" name="gazebo_ros_control">
      <robotNamespace>/</robotNamespace>
    </plugin>
  </gazebo>
  <gazebo reference="panda_link0"/>
  <gazebo reference="panda_link1"/>
  <gazebo reference="panda_link2"/>
  <gazebo reference="panda_link3"/>
  <gazebo reference="panda_link4"/>
  <gazebo reference="panda_link5"/>
  <gazebo reference="panda_link6"/>
  <gazebo reference="panda_link7"/>
  <gazebo reference="panda_link8"/>
  <transmission name="panda_joint1_trans">
    <type>transmission_interface/SimpleTransmission</type>
    <joint name="panda_joint1">
      <hardwareInterface>hardware_interface/PositionJointInterface</hardwareInterface>
    </joint>
    <actuator name="panda_joint1_motor">
      <mechanicalReduction>1</mechanicalReduction>
    </actuator>
  </transmission>
  <transmission name="panda_joint2_trans">
    <type>transmission_interface/SimpleTransmission</type>
    <joint name="panda_joint2">
      <hardwareInterface>hardware_interface/PositionJointInterface</hardwareInterface>
    </joint>
    <actuator name="panda_joint2_motor">
      <mechanicalReduction>1</mechanicalReduction>
    </actuator>
  </transmission>
  <transmission name="panda_joint3_trans">
    <type>transmission_interface/SimpleTransmission</type>
    <joint name="panda_joint3">
      <hardwareInterface>hardware_interface/PositionJointInterface</hardwareInterface>
    </joint>
    <actuator name="panda_joint3_motor">
      <mechanicalReduction>1</mechanicalReduction>
    </actuator>
  </transmission>
  <transmission name="panda_joint4_trans">
    <type>transmission_interface/SimpleTransmission</type>
    <joint name="panda_joint4">
      <hardwareInterface>hardware_interface/PositionJointInterface</hardwareInterface>
    </joint>
    <actuator name="panda_joint4_motor">
      <mechanicalReduction>1</mechanicalReduction>
    </actuator>
  </transmission>
  <transmission name="panda_joint5_trans">
    <type>transmission_interface/SimpleTransmission</type>
    <joint name="panda_joint5">
      <hardwareInterface>hardware_interface/PositionJointInterface</hardwareInterface>
    </joint>
    <actuator name="panda_joint5_motor">
      <mechanicalReduction>1</mechanicalReduction>
    </actuator>
  </transmission>
  <transmission name="panda_joint6_trans">
    <type>transmission_interface/SimpleTransmission</type>
    <joint name="panda_joint6">
      <hardwareInterface>hardware_interface/PositionJointInterface</hardwareInterface>
    </joint>
    <actuator name="panda_joint6_motor">
      <mechanicalReduction>1</mechanicalReduction>
    </actuator>
  </transmission>
  <transmission name="panda_joint7_trans">
    <type>transmission_interface/SimpleTransmission</type>
    <joint name="panda_joint7">
      <hardwareInterface>hardware_interface/PositionJointInterface</hardwareInterface>
    </joint>
    <actuator name="panda_joint7_motor">
      <mechanicalReduction>1</mechanicalReduction>
    </actuator>
  </transmission>
  <material name="redtran">
    <color rgba=".9 .1 .1 0.3"/>
  </material>
  <material name="greentran">
    <color rgba=".1 .9 .1 0.3"/>
  </material>
  <material name="bluetran">
    <color rgba=".1 .1 .9 0.3"/>
  </material>
  <link name="panda_link0">
    <inertial>
      <mass value="2.92"/>
      <origin rpy="0 0 0" xyz="-0.025566 -2.88e-05 0.057332"/>
      <inertia ixx="0.00782229414331" ixy="-1.56191622996e-05" ixz="-0.00126005738123" iyy="0.0109027971813" iyz="1.08233858202e-05" izz="0.0102355503949"/>
    </inertial>
    <visual>
      <origin rpy="0 0 0" xyz="0 0 0"/>
      <geometry>
        <mesh filename="package://franka_description/meshes/visual/link0.dae"/>
      </geometry>
      <material name="">
        <color rgba="1 1 1 1"/>
      </material>
    </visual>
    <visual>
      <origin xyz="0 0 .117"/>
      <geometry> <sphere radius=".06"/> </geometry>
      <material name="redtran"/>
    </visual>
    <visual>
      <origin xyz="0 0 .042"/>
      <geometry> <sphere radius=".085"/> </geometry>
      <material name="redtran"/>
    </visual>
    <visual>
      <origin xyz="-.029 0 .061"/>
      <geometry> <sphere radius=".075"/> </geometry>
      <material name="redtran"/>
    </visual>
    <visual>
      <origin xyz="-.068 0 .024"/>
      <geometry> <sphere radius=".075"/> </geometry>
      <material name="redtran"/>
    </visual>
    <collision>
      <origin rpy="0 0 0" xyz="0 0 0"/>
      <geometry>
        <mesh filename="package://franka_description/meshes/collision/link0.stl"/>
      </geometry>
    </collision>
  </link>
  <link name="panda_link1">
    <inertial>
      <mass value="2.74"/>
      <origin rpy="0 0 0" xyz="0 -0.0324958 -0.0675818"/>
      <inertia ixx="0.0180416958283" ixy="0.0" ixz="0.0" iyy="0.0159136071891" iyz="0.0046758424612" izz="0.00620690827127"/>
    </inertial>
    <visual>
      <origin rpy="0 0 0" xyz="0 0 0"/>
      <geometry>
        <mesh filename="package://franka_description/meshes/visual/link1.dae"/>
      </geometry>
      <material name="">
        <color rgba="1 1 1 1"/>
      </material>
    </visual>
    <visual>
      <origin xyz="0 -.071 0"/>
      <geometry> <sphere radius=".06"/> </geometry>
      <material name="greentran"/>
    </visual>
    <visual>
      <origin xyz="0 -.024 0"/>
      <geometry> <sphere radius=".061"/> </geometry>
      <material name="greentran"/>
    </visual>
    <visual>
      <origin xyz="0 -.001 -.134"/>
      <geometry> <sphere radius=".059"/> </geometry>
      <material name="greentran"/>
    </visual>
    <visual>
      <origin xyz="0 0 -.17"/>
      <geometry> <sphere radius=".06"/> </geometry>
      <material name="greentran"/>
    </visual>
    <visual>
      <origin xyz=".015 -.048 -.032"/>
      <geometry> <sphere radius=".047"/> </geometry>
      <material name="greentran"/>
    </visual>
    <visual>
      <origin xyz="-.015 -.048 -.032"/>
      <geometry> <sphere radius=".047"/> </geometry>
      <material name="greentran"/>
    </visual>
    <visual>
      <origin xyz="0 -.054 -.047"/>
      <geometry> <sphere radius=".047"/> </geometry>
      <material name="greentran"/>
    </visual>
    <visual>
      <origin xyz=".026 -.035 -.069"/>
      <geometry> <sphere radius=".035"/> </geometry>
      <material name="greentran"/>
    </visual>
    <visual>
      <origin xyz=".036 -.011 -.103"/>
      <geometry> <sphere radius=".03"/> </geometry>
      <material name="greentran"/>
    </visual>
    <visual>
      <origin xyz="-.026 -.035 -.069"/>
      <geometry> <sphere radius=".035"/> </geometry>
      <material name="greentran"/>
    </visual>
    <visual>
      <origin xyz="-.036 -.011 -.103"/>
      <geometry> <sphere radius=".03"/> </geometry>
      <material name="greentran"/>
    </visual>
    <visual>
      <origin xyz=".011 -.028 -.093"/>
      <geometry> <sphere radius=".044"/> </geometry>
      <material name="greentran"/>
    </visual>
    <visual>
      <origin xyz="-.011 -.028 -.093"/>
      <geometry> <sphere radius=".044"/> </geometry>
      <material name="greentran"/>
    </visual>
    <collision>
      <origin rpy="0 0 0" xyz="0 0 0"/>
      <geometry>
        <mesh filename="package://franka_description/meshes/collision/link1.stl"/>
      </geometry>
    </collision>
  </link>
  <joint name="panda_joint1" type="revolute">
    <safety_controller k_position="100.0" k_velocity="40.0" soft_lower_limit="-2.8973" soft_upper_limit="2.8973"/>
    <origin rpy="0 0 0" xyz="0 0 0.333"/>
    <parent link="panda_link0"/>
    <child link="panda_link1"/>
    <axis xyz="0 0 1"/>
    <limit effort="87" lower="-2.8973" upper="2.8973" velocity="2.1750"/>
  </joint>
  <link name="panda_link2">
    <inertial>
      <mass value="2.74"/>
      <origin rpy="0 0 0" xyz="0 -0.06861 0.0322285"/>
      <inertia ixx="0.0182856182281" ixy="0.0" ixz="0.0" iyy="0.00621358421175" iyz="-0.00472844221905" izz="0.0161514346309"/>
    </inertial>
    <visual>
      <origin rpy="0 0 0" xyz="0 0 0"/>
      <geometry>
        <mesh filename="package://franka_description/meshes/visual/link2.dae"/>
      </geometry>
      <material name="">
        <color rgba="1 1 1 1"/>
      </material>
    </visual>
    <visual>
      <origin xyz="0 -.128 .001"/>
      <geometry> <sphere radius=".061"/> </geometry>
      <material name="redtran"/>
    </visual>
    <visual>
      <origin xyz="0 0 .023"/>
      <geometry> <sphere radius=".061"/> </geometry>
      <material name="redtran"/>
    </visual>
    <visual>
      <origin xyz="-.016 -.045 .051"/>
      <geometry> <sphere radius=".052"/> </geometry>
      <material name="redtran"/>
    </visual>
    <visual>
      <origin xyz=".021 -.097 .032"/>
      <geometry> <sphere radius=".043"/> </geometry>
      <material name="redtran"/>
    </visual>
    <visual>
      <origin xyz="0 0 .07"/>
      <geometry> <sphere radius=".061"/> </geometry>
      <material name="redtran"/>
    </visual>
    <visual>
      <origin xyz="0 -.173 0"/>
      <geometry> <sphere radius=".061"/> </geometry>
      <material name="redtran"/>
    </visual>
    <visual>
      <origin xyz=".016 -.045 .051"/>
      <geometry> <sphere radius=".052"/> </geometry>
      <material name="redtran"/>
    </visual>
    <visual>
      <origin xyz="-.021 -.097 .032"/>
      <geometry> <sphere radius=".043"/> </geometry>
      <material name="redtran"/>
    </visual>
    <collision>
      <origin rpy="0 0 0" xyz="0 0 0"/>
      <geometry>
        <mesh filename="package://franka_description/meshes/collision/link2.stl"/>
      </geometry>
    </collision>
  </link>
  <joint name="panda_joint2" type="revolute">
    <safety_controller k_position="100.0" k_velocity="40.0" soft_lower_limit="-1.7628" soft_upper_limit="1.7628"/>
    <origin rpy="-1.57079632679 0 0" xyz="0 0 0"/>
    <parent link="panda_link1"/>
    <child link="panda_link2"/>
    <axis xyz="0 0 1"/>
    <limit effort="87" lower="-1.7628" upper="1.7628" velocity="2.1750"/>
  </joint>
  <link name="panda_link3">
    <inertial>
      <mass value="2.38"/>
      <origin rpy="0 0 0" xyz="0.0469893 0.0316374 -0.031704"/>
      <inertia ixx="0.00771376630908" ixy="-0.00248490625138" ixz="-0.00332147581033" iyy="0.00989108008727" iyz="-0.00217796151484" izz="0.00811723558464"/>
    </inertial>
    <visual>
      <origin rpy="0 0 0" xyz="0 0 0"/>
      <geometry>
        <mesh filename="package://franka_description/meshes/visual/link3.dae"/>
      </geometry>
      <material name="">
        <color rgba="1 1 1 1"/>
      </material>
    </visual>
    <visual>
      <origin xyz=".045 .026 -.032"/>
      <geometry> <sphere radius=".059"/> </geometry>
      <material name="greentran"/>
    </visual>
    <visual>
      <origin xyz=".084 .017 -.001"/>
      <geometry> <sphere radius=".06"/> </geometry>
      <material name="greentran"/>
    </visual>
    <visual>
      <origin xyz=".081 .062 0"/>
      <geometry> <sphere radius=".059"/> </geometry>
      <material name="greentran"/>
    </visual>
    <visual>
      <origin xyz="0 .001 -.105"/>
      <geometry> <sphere radius=".06"/> </geometry>
      <material name="greentran"/>
    </visual>
    <visual>
      <origin xyz=".002 0 -.069"/>
      <geometry> <sphere radius=".059"/> </geometry>
      <material name="greentran"/>
    </visual>
    <collision>
      <origin rpy="0 0 0" xyz="0 0 0"/>
      <geometry>
        <mesh filename="package://franka_description/meshes/collision/link3.stl"/>
      </geometry>
    </collision>
  </link>
  <joint name="panda_joint3" type="revolute">
    <safety_controller k_position="100.0" k_velocity="40.0" soft_lower_limit="-2.8973" soft_upper_limit="2.8973"/>
    <origin rpy="1.57079632679 0 0" xyz="0 -0.316 0"/>
    <parent link="panda_link2"/>
    <child link="panda_link3"/>
    <axis xyz="0 0 1"/>
    <limit effort="87" lower="-2.8973" upper="2.8973" velocity="2.1750"/>
  </joint>
  <link name="panda_link4">
    <inertial>
      <mass value="2.38"/>
      <origin rpy="0 0 0" xyz="-0.0360446 0.0336853 0.031882"/>
      <inertia ixx="0.00799663881132" ixy="0.00347095570217" ixz="-0.00241222942995" iyy="0.00825390705278" iyz="0.00235774044121" izz="0.0102515004345"/>
    </inertial>
    <visual>
      <origin rpy="0 0 0" xyz="0 0 0"/>
      <geometry>
        <mesh filename="package://franka_description/meshes/visual/link4.dae"/>
      </geometry>
      <material name="">
        <color rgba="1 1 1 1"/>
      </material>
    </visual>
    <visual>
      <origin xyz="0 0 .062"/>
      <geometry> <sphere radius=".057"/> </geometry>
      <material name="redtran"/>
    </visual>
    <visual>
      <origin xyz="0 0 .018"/>
      <geometry> <sphere radius=".059"/> </geometry>
      <material name="redtran"/>
    </visual>
    <visual>
      <origin xyz="-.022 .019 .04"/>
      <geometry> <sphere radius=".058"/> </geometry>
      <material name="redtran"/>
    </visual>
    <visual>
      <origin xyz="-.082 .111 0"/>
      <geometry> <sphere radius=".058"/> </geometry>
      <material name="redtran"/>
    </visual>
    <visual>
      <origin xyz="-.084 .069 0"/>
      <geometry> <sphere radius=".059"/> </geometry>
      <material name="redtran"/>
    </visual>
    <visual>
      <origin xyz="-.071 .057 .002"/>
      <geometry> <sphere radius=".059"/> </geometry>
      <material name="redtran"/>
    </visual>
    <collision>
      <origin rpy="0 0 0" xyz="0 0 0"/>
      <geometry>
        <mesh filename="package://franka_description/meshes/collision/link4.stl"/>
      </geometry>
    </collision>
  </link>
  <joint name="panda_joint4" type="revolute">
    <safety_controller k_position="100.0" k_velocity="40.0" soft_lower_limit="-3.0718" soft_upper_limit="0.0698"/>
    <!-- soft_upper_limitr should be -0.0698, but that brakes simulation when initial position for this joint is 0.0 -->
    <origin rpy="1.57079632679 0 0" xyz="0.0825 0 0"/>
    <parent link="panda_link3"/>
    <child link="panda_link4"/>
    <axis xyz="0 0 1"/>
    <limit effort="87" lower="-3.0718" upper="0.0698" velocity="2.1750"/>
    <!-- upper should be -0.0698, but that brakes simulation when initial position for this joint is 0.0 -->
  </joint>
  <link name="panda_link5">
    <inertial>
      <mass value="2.74"/>
      <origin rpy="0 0 0" xyz="0 0.0610427 -0.104176"/>
      <inertia ixx="0.030371374513" ixy="6.50283587108e-07" ixz="-1.05129179916e-05" iyy="0.0288752887402" iyz="-0.00775653445787" izz="0.00444134056164"/>
    </inertial>
    <visual>
      <origin rpy="0 0 0" xyz="0 0 0"/>
      <geometry>
        <mesh filename="package://franka_description/meshes/visual/link5.dae"/>
      </geometry>
      <material name="">
        <color rgba="1 1 1 1"/>
      </material>
    </visual>
    <visual>
      <origin xyz="0 .021 -.197"/>
      <geometry> <sphere radius=".053"/> </geometry>
      <material name="greentran"/>
    </visual>
    <visual>
      <origin xyz="-.018 .096 -.036"/>
      <geometry> <sphere radius=".03"/> </geometry>
      <material name="greentran"/>
    </visual>
    <visual>
      <origin xyz="0 .085 0"/>
      <geometry> <sphere radius=".055"/> </geometry>
      <material name="greentran"/>
    </visual>
    <visual>
      <origin xyz=".018 .096 -.036"/>
      <geometry> <sphere radius=".03"/> </geometry>
      <material name="greentran"/>
    </visual>
    <visual>
      <origin xyz="0 .037 0"/>
      <geometry> <sphere radius=".053"/> </geometry>
      <material name="greentran"/>
    </visual>
    <visual>
      <origin xyz="0 .001 -.233"/>
      <geometry> <sphere radius=".062"/> </geometry>
      <material name="greentran"/>
    </visual>
    <visual>
      <origin xyz="0 .059 -.178"/>
      <geometry> <sphere radius=".043"/> </geometry>
      <material name="greentran"/>
    </visual>
    <visual>
      <origin xyz=".015 .077 -.147"/>
      <geometry> <sphere radius=".027"/> </geometry>
      <material name="greentran"/>
    </visual>
    <visual>
      <origin xyz="-.015 .091 -.076"/>
      <geometry> <sphere radius=".027"/> </geometry>
      <material name="greentran"/>
    </visual>
    <visual>
      <origin xyz="0 .094 -.053"/>
      <geometry> <sphere radius=".024"/> </geometry>
      <material name="greentran"/>
    </visual>
    <visual>
      <origin xyz=".015 .087 -.112"/>
      <geometry> <sphere radius=".027"/> </geometry>
      <material name="greentran"/>
    </visual>
    <visual>
      <origin xyz="-.015 .087 -.112"/>
      <geometry> <sphere radius=".027"/> </geometry>
      <material name="greentran"/>
    </visual>
    <visual>
      <origin xyz=".015 .091 -.076"/>
      <geometry> <sphere radius=".027"/> </geometry>
      <material name="greentran"/>
    </visual>
    <visual>
      <origin xyz="-.015 .077 -.147"/>
      <geometry> <sphere radius=".027"/> </geometry>
      <material name="greentran"/>
    </visual>
    <visual>
      <origin xyz="0 .081 -.132"/>
      <geometry> <sphere radius=".024"/> </geometry>
      <material name="greentran"/>
    </visual>
    <visual>
      <origin xyz="0 .087 -.092"/>
      <geometry> <sphere radius=".022"/> </geometry>
      <material name="greentran"/>
    </visual>
    <collision>
      <origin rpy="0 0 0" xyz="0 0 0"/>
      <geometry>
        <mesh filename="package://franka_description/meshes/collision/link5.stl"/>
      </geometry>
    </collision>
  </link>
  <joint name="panda_joint5" type="revolute">
    <safety_controller k_position="100.0" k_velocity="40.0" soft_lower_limit="-2.8973" soft_upper_limit="2.8973"/>
    <origin rpy="-1.57079632679 0 0" xyz="-0.0825 0.384 0"/>
    <parent link="panda_link4"/>
    <child link="panda_link5"/>
    <axis xyz="0 0 1"/>
    <limit effort="12" lower="-2.8973" upper="2.8973" velocity="2.6100"/>
  </joint>
  <link name="panda_link6">
    <inertial>
      <mass value="1.55"/>
      <origin rpy="0 0 0" xyz="0.0510509 0.009108 0.0106343"/>
      <inertia ixx="0.00303336450376" ixy="-0.000437276865508" ixz="0.000629257294877" iyy="0.00404479911567" iyz="0.000130472021025" izz="0.00558234286039"/>
    </inertial>
    <visual>
      <origin rpy="0 0 0" xyz="0 0 0"/>
      <geometry>
        <mesh filename="package://franka_description/meshes/visual/link6.dae"/>
      </geometry>
      <material name="">
        <color rgba="1 1 1 1"/>
      </material>
    </visual>
    <visual>
      <origin xyz=".087 -.03 .0"/>
      <geometry> <sphere radius=".05"/> </geometry>
      <material name="redtran"/>
    </visual>
    <visual>
      <origin xyz=".028 .011 .009"/>
      <geometry> <sphere radius=".059"/> </geometry>
      <material name="redtran"/>
    </visual>
    <visual>
      <origin xyz="-.001 0 .012"/>
      <geometry> <sphere radius=".055"/> </geometry>
      <material name="redtran"/>
    </visual>
    <visual>
      <origin xyz=".079 .04 0"/>
      <geometry> <sphere radius=".052"/> </geometry>
      <material name="redtran"/>
    </visual>
    <visual>
      <origin xyz=".09 .01 .0"/>
      <geometry> <sphere radius=".049"/> </geometry>
      <material name="redtran"/>
    </visual>
    <collision>
      <origin rpy="0 0 0" xyz="0 0 0"/>
      <geometry>
        <mesh filename="package://franka_description/meshes/collision/link6.stl"/>
      </geometry>
    </collision>
  </link>
  <joint name="panda_joint6" type="revolute">
    <safety_controller k_position="100.0" k_velocity="40.0" soft_lower_limit="-0.0175" soft_upper_limit="3.7525"/>
    <origin rpy="1.57079632679 0 0" xyz="0 0 0"/>
    <parent link="panda_link5"/>
    <child link="panda_link6"/>
    <axis xyz="0 0 1"/>
    <limit effort="12" lower="-0.0175" upper="3.7525" velocity="2.6100"/>
  </joint>
  <link name="panda_link7">
    <inertial>
      <mass value="0.54"/>
      <origin rpy="0 0 0" xyz="0.0109695 0.0107965 0.0650411"/>
      <inertia ixx="0.000888868887021" ixy="-0.00012239074652" ixz="3.98699829666e-05" iyy="0.000888001373233" iyz="-9.33825115206e-05" izz="0.0007176834609"/>
    </inertial>
    <visual>
      <origin rpy="0 0 0" xyz="0 0 0"/>
      <geometry>
        <mesh filename="package://franka_description/meshes/visual/link7.dae"/>
      </geometry>
      <material name="">
        <color rgba="1 1 1 1"/>
      </material>
    </visual>
    <visual>
      <origin xyz=".0 .0 .075"/>
      <geometry> <sphere radius=".05"/> </geometry>
      <material name="greentran"/>
    </visual>
    <visual>
      <origin xyz=".016 .042 .079"/>
      <geometry> <sphere radius=".028"/> </geometry>
      <material name="greentran"/>
    </visual>
    <visual>
      <origin xyz=".041 .012 .079"/>
      <geometry> <sphere radius=".028"/> </geometry>
      <material name="greentran"/>
    </visual>
    <visual>
      <origin xyz=".04 .058 .085"/>
      <geometry> <sphere radius=".026"/> </geometry>
      <material name="greentran"/>
    </visual>
    <visual>
      <origin xyz=".058 .037 .083"/>
      <geometry> <sphere radius=".026"/> </geometry>
      <material name="greentran"/>
    </visual>
    <collision>
      <origin rpy="0 0 0" xyz="0 0 0"/>
      <geometry>
        <mesh filename="package://franka_description/meshes/collision/link7.stl"/>
      </geometry>
    </collision>
  </link>
  <joint name="panda_joint7" type="revolute">
    <safety_controller k_position="100.0" k_velocity="40.0" soft_lower_limit="-2.8973" soft_upper_limit="2.8973"/>
    <origin rpy="1.57079632679 0 0" xyz="0.088 0 0"/>
    <parent link="panda_link6"/>
    <child link="panda_link7"/>
    <axis xyz="0 0 1"/>
    <limit effort="12" lower="-2.8973" upper="2.8973" velocity="2.6100"/>
  </joint>
  <link name="panda_link8"/>
  <joint name="panda_joint8" type="fixed">
    <origin rpy="0 0 0" xyz="0 0 0.107"/>
    <parent link="panda_link7"/>
    <child link="panda_link8"/>
    <axis xyz="0 0 0"/>
  </joint>
</robot>

