<?xml version="1.0" ?>
<!-- =================================================================================== -->
<!-- |    This document was autogenerated by xacro from hand.urdf.xacro                | -->
<!-- |    EDITING THIS FILE BY HAND IS NOT RECOMMENDED                                 | -->
<!-- =================================================================================== -->
<robot name="hand" xmlns:xacro="http://www.ros.org/wiki/xacro">
  <material name="redtran">
    <color rgba=".9 .1 .1 0.3"/>
  </material>
  <material name="greentran">
    <color rgba=".1 .9 .1 0.3"/>
  </material>
  <material name="bluetran">
    <color rgba=".1 .1 .9 0.3"/>
  </material>
  <link name="panda_hand">
    <visual>
      <geometry>
        <mesh filename="package://franka_description/meshes/visual/hand.dae"/>
      </geometry>
    </visual>
    <collision>
      <origin xyz="0 -.077 .041"/>
      <geometry>
        <sphere radius="0.033"/>
      </geometry>
      <material name="redtran"/>
    </collision>
    <collision>
      <origin xyz="0 .075 .012"/>
      <geometry>
        <sphere radius="0.033"/>
      </geometry>
      <material name="redtran"/>
    </collision>
    <collision>
      <origin xyz="0 .077 .041"/>
      <geometry>
        <sphere radius="0.033"/>
      </geometry>
      <material name="redtran"/>
    </collision>
    <collision>
      <origin xyz="0 -.05 .002"/>
      <geometry>
        <sphere radius="0.033"/>
      </geometry>
      <material name="redtran"/>
    </collision>
    <collision>
      <origin xyz="0 -.046 .041"/>
      <geometry>
        <sphere radius="0.033"/>
      </geometry>
      <material name="redtran"/>
    </collision>
    <collision>
      <origin xyz="0 .046 .041"/>
      <geometry>
        <sphere radius="0.033"/>
      </geometry>
      <material name="redtran"/>
    </collision>
    <collision>
      <origin xyz="0 .016 .041"/>
      <geometry>
        <sphere radius="0.033"/>
      </geometry>
      <material name="redtran"/>
    </collision>
    <collision>
      <origin xyz="0 -.016 .041"/>
      <geometry>
        <sphere radius="0.033"/>
      </geometry>
      <material name="redtran"/>
    </collision>
    <collision>
      <origin xyz="0 -.075 .002"/>
      <geometry>
        <sphere radius="0.033"/>
      </geometry>
      <material name="redtran"/>
    </collision>
    <collision>
      <origin xyz="0 .051 .003"/>
      <geometry>
        <sphere radius="0.033"/>
      </geometry>
      <material name="redtran"/>
    </collision>
    <collision>
      <origin xyz="0 0 .003"/>
      <geometry>
        <sphere radius="0.033"/>
      </geometry>
      <material name="redtran"/>
    </collision>
  </link>
  <link name="panda_leftfinger">
    <visual>
      <geometry>
        <mesh filename="package://franka_description/meshes/visual/finger.dae"/>
      </geometry>
    </visual>
    <collision>
      <origin xyz="0 .014 .022"/>
      <geometry>
        <sphere radius="0.017"/>
      </geometry>
      <material name="greentran"/>
    </collision>
    <collision>
      <origin xyz="0 .015 .005"/>
      <geometry>
        <sphere radius="0.018"/>
      </geometry>
      <material name="greentran"/>
    </collision>
    <collision>
      <origin xyz="0 .008 .044"/>
      <geometry>
        <sphere radius="0.014"/>
      </geometry>
      <material name="greentran"/>
    </collision>
  </link>
  <link name="panda_rightfinger">
    <visual>
      <origin rpy="0 0 3.14159265359" xyz="0 0 0"/>
      <geometry>
        <mesh filename="package://franka_description/meshes/visual/finger.dae"/>
      </geometry>
    </visual>
    <collision>
      <origin xyz="0 -.014 .022"/>
      <geometry>
        <sphere radius="0.017"/>
      </geometry>
      <material name="greentran"/>
    </collision>
    <collision>
      <origin xyz="0 -.015 .005"/>
      <geometry>
        <sphere radius="0.018"/>
      </geometry>
      <material name="greentran"/>
    </collision>
    <collision>
      <origin xyz="0 -.008 .044"/>
      <geometry>
        <sphere radius="0.014"/>
      </geometry>
      <material name="greentran"/>
    </collision>
  </link>
  <link name="panda_hand_center"/>
  <joint name="panda_finger_joint1" type="prismatic">
    <parent link="panda_hand"/>
    <child link="panda_leftfinger"/>
    <origin rpy="0 0 0" xyz="0 0 0.0584"/>
    <axis xyz="0 1 0"/>
    <limit effort="20" lower="0.0" upper="0.04" velocity="0.2"/>
  </joint>
  <joint name="panda_finger_joint2" type="prismatic">
    <parent link="panda_hand"/>
    <child link="panda_rightfinger"/>
    <origin rpy="0 0 0" xyz="0 0 0.0584"/>
    <axis xyz="0 -1 0"/>
    <limit effort="20" lower="0.0" upper="0.04" velocity="0.2"/>
    <mimic joint="panda_finger_joint1"/>
  </joint>
  <joint name="panda_hand_center_joint" type="fixed">
    <parent link="panda_hand"/>
    <child link="panda_hand_center"/>
    <origin rpy="0 0 0" xyz="0 0 0.09"/>
  </joint>
</robot>

