<?xml version="1.0" ?>
<!-- =================================================================================== -->
<!-- |    This document was autogenerated by xacro from table_mug_panda_arm_hand_fingers_fixed.urdf.xacro | -->
<!-- |    EDITING THIS FILE BY HAND IS NOT RECOMMENDED                                 | -->
<!-- =================================================================================== -->
<robot name="panda" xmlns:xacro="http://www.ros.org/wiki/xacro">
  <link name="table">
    <visual>
      <origin rpy="0 0 0" xyz="1.3716 1.8288 -0.1524"/>
      <geometry>
        <box size="2.7432 3.6576 0.3048"/>
      </geometry>
      <material name="grey">
        <color rgba="0.5 0.5 0.5 1.0"/>
      </material>
    </visual>
    <visual>
      <origin rpy="0 0 0" xyz="0.4953 -0.18288 -0.02032"/>
      <geometry>
        <box size="0.3048 0.36576 0.09144"/>
      </geometry>
      <material name="black">
        <color rgba="0.15 0.15 0.15 1.0"/>
      </material>
    </visual>
  </link>
  <material name="redtran">
    <color rgba=".9 .1 .1 0.3"/>
  </material>
  <material name="greentran">
    <color rgba=".1 .9 .1 0.3"/>
  </material>
  <material name="bluetran">
    <color rgba=".1 .1 .9 0.3"/>
  </material>
  <joint name="panda_joint_table" type="fixed">
    <parent link="table"/>
    <child link="panda_link0"/>
    <origin rpy="0 0 1.57079632679" xyz="0.4953 -0.10795 0.0"/>
  </joint>
  <link name="panda_link0">
    <visual>
      <geometry>
        <mesh filename="package://franka_description/meshes/visual/link0.dae"/>
      </geometry>
    </visual>
    <collision>
      <origin xyz="0 0 .117"/>
      <geometry>
        <sphere radius="0.06"/>
      </geometry>
      <material name="redtran"/>
    </collision>
    <collision>
      <origin xyz="0 0 .042"/>
      <geometry>
        <sphere radius="0.085"/>
      </geometry>
      <material name="redtran"/>
    </collision>
    <collision>
      <origin xyz="-.029 0 .061"/>
      <geometry>
        <sphere radius="0.075"/>
      </geometry>
      <material name="redtran"/>
    </collision>
    <collision>
      <origin xyz="-.068 0 .024"/>
      <geometry>
        <sphere radius="0.075"/>
      </geometry>
      <material name="redtran"/>
    </collision>
  </link>
  <link name="panda_link1">
    <visual>
      <geometry>
        <mesh filename="package://franka_description/meshes/visual/link1.dae"/>
      </geometry>
    </visual>
    <collision>
      <origin xyz="0 -.071 0"/>
      <geometry>
        <sphere radius="0.06"/>
      </geometry>
      <material name="greentran"/>
    </collision>
    <collision>
      <origin xyz="0 -.024 0"/>
      <geometry>
        <sphere radius="0.061"/>
      </geometry>
      <material name="greentran"/>
    </collision>
    <collision>
      <origin xyz="0 -.001 -.134"/>
      <geometry>
        <sphere radius="0.059"/>
      </geometry>
      <material name="greentran"/>
    </collision>
    <collision>
      <origin xyz="0 0 -.17"/>
      <geometry>
        <sphere radius="0.06"/>
      </geometry>
      <material name="greentran"/>
    </collision>
    <collision>
      <origin xyz=".015 -.048 -.032"/>
      <geometry>
        <sphere radius="0.047"/>
      </geometry>
      <material name="greentran"/>
    </collision>
    <collision>
      <origin xyz="-.015 -.048 -.032"/>
      <geometry>
        <sphere radius="0.047"/>
      </geometry>
      <material name="greentran"/>
    </collision>
    <collision>
      <origin xyz="0 -.054 -.047"/>
      <geometry>
        <sphere radius="0.047"/>
      </geometry>
      <material name="greentran"/>
    </collision>
    <collision>
      <origin xyz=".026 -.035 -.069"/>
      <geometry>
        <sphere radius="0.035"/>
      </geometry>
      <material name="greentran"/>
    </collision>
    <collision>
      <origin xyz=".036 -.011 -.103"/>
      <geometry>
        <sphere radius="0.03"/>
      </geometry>
      <material name="greentran"/>
    </collision>
    <collision>
      <origin xyz="-.026 -.035 -.069"/>
      <geometry>
        <sphere radius="0.035"/>
      </geometry>
      <material name="greentran"/>
    </collision>
    <collision>
      <origin xyz="-.036 -.011 -.103"/>
      <geometry>
        <sphere radius="0.03"/>
      </geometry>
      <material name="greentran"/>
    </collision>
    <collision>
      <origin xyz=".011 -.028 -.093"/>
      <geometry>
        <sphere radius="0.044"/>
      </geometry>
      <material name="greentran"/>
    </collision>
    <collision>
      <origin xyz="-.011 -.028 -.093"/>
      <geometry>
        <sphere radius="0.044"/>
      </geometry>
      <material name="greentran"/>
    </collision>
  </link>
  <joint name="panda_joint1" type="revolute">
    <safety_controller k_position="100.0" k_velocity="40.0" soft_lower_limit="-2.8973" soft_upper_limit="2.8973"/>
    <origin rpy="0 0 0" xyz="0 0 0.333"/>
    <parent link="panda_link0"/>
    <child link="panda_link1"/>
    <axis xyz="0 0 1"/>
    <limit effort="87" lower="-2.8973" upper="2.8973" velocity="2.1750"/>
  </joint>
  <link name="panda_link2">
    <visual>
      <geometry>
        <mesh filename="package://franka_description/meshes/visual/link2.dae"/>
      </geometry>
    </visual>
    <collision>
      <origin xyz="0 -.128 .001"/>
      <geometry>
        <sphere radius="0.061"/>
      </geometry>
      <material name="redtran"/>
    </collision>
    <collision>
      <origin xyz="0 0 .023"/>
      <geometry>
        <sphere radius="0.061"/>
      </geometry>
      <material name="redtran"/>
    </collision>
    <collision>
      <origin xyz="-.016 -.045 .051"/>
      <geometry>
        <sphere radius="0.052"/>
      </geometry>
      <material name="redtran"/>
    </collision>
    <collision>
      <origin xyz=".021 -.097 .032"/>
      <geometry>
        <sphere radius="0.043"/>
      </geometry>
      <material name="redtran"/>
    </collision>
    <collision>
      <origin xyz="0 0 .07"/>
      <geometry>
        <sphere radius="0.061"/>
      </geometry>
      <material name="redtran"/>
    </collision>
    <collision>
      <origin xyz="0 -.173 0"/>
      <geometry>
        <sphere radius="0.061"/>
      </geometry>
      <material name="redtran"/>
    </collision>
    <collision>
      <origin xyz=".016 -.045 .051"/>
      <geometry>
        <sphere radius="0.052"/>
      </geometry>
      <material name="redtran"/>
    </collision>
    <collision>
      <origin xyz="-.021 -.097 .032"/>
      <geometry>
        <sphere radius="0.043"/>
      </geometry>
      <material name="redtran"/>
    </collision>
  </link>
  <joint name="panda_joint2" type="revolute">
    <safety_controller k_position="100.0" k_velocity="40.0" soft_lower_limit="-1.7628" soft_upper_limit="1.7628"/>
    <origin rpy="-1.57079632679 0 0" xyz="0 0 0"/>
    <parent link="panda_link1"/>
    <child link="panda_link2"/>
    <axis xyz="0 0 1"/>
    <limit effort="87" lower="-1.7628" upper="1.7628" velocity="2.1750"/>
  </joint>
  <link name="panda_link3">
    <visual>
      <geometry>
        <mesh filename="package://franka_description/meshes/visual/link3.dae"/>
      </geometry>
    </visual>
    <collision>
      <origin xyz=".045 .026 -.032"/>
      <geometry>
        <sphere radius="0.059"/>
      </geometry>
      <material name="greentran"/>
    </collision>
    <collision>
      <origin xyz=".084 .017 -.001"/>
      <geometry>
        <sphere radius="0.06"/>
      </geometry>
      <material name="greentran"/>
    </collision>
    <collision>
      <origin xyz=".081 .062 0"/>
      <geometry>
        <sphere radius="0.059"/>
      </geometry>
      <material name="greentran"/>
    </collision>
    <collision>
      <origin xyz="0 .001 -.105"/>
      <geometry>
        <sphere radius="0.06"/>
      </geometry>
      <material name="greentran"/>
    </collision>
    <collision>
      <origin xyz=".002 0 -.069"/>
      <geometry>
        <sphere radius="0.059"/>
      </geometry>
      <material name="greentran"/>
    </collision>
  </link>
  <joint name="panda_joint3" type="revolute">
    <safety_controller k_position="100.0" k_velocity="40.0" soft_lower_limit="-2.8973" soft_upper_limit="2.8973"/>
    <origin rpy="1.57079632679 0 0" xyz="0 -0.316 0"/>
    <parent link="panda_link2"/>
    <child link="panda_link3"/>
    <axis xyz="0 0 1"/>
    <limit effort="87" lower="-2.8973" upper="2.8973" velocity="2.1750"/>
  </joint>
  <link name="panda_link4">
    <visual>
      <geometry>
        <mesh filename="package://franka_description/meshes/visual/link4.dae"/>
      </geometry>
    </visual>
    <collision>
      <origin xyz="0 0 .062"/>
      <geometry>
        <sphere radius="0.057"/>
      </geometry>
      <material name="redtran"/>
    </collision>
    <collision>
      <origin xyz="0 0 .018"/>
      <geometry>
        <sphere radius="0.059"/>
      </geometry>
      <material name="redtran"/>
    </collision>
    <collision>
      <origin xyz="-.022 .019 .04"/>
      <geometry>
        <sphere radius="0.058"/>
      </geometry>
      <material name="redtran"/>
    </collision>
    <collision>
      <origin xyz="-.082 .111 0"/>
      <geometry>
        <sphere radius="0.058"/>
      </geometry>
      <material name="redtran"/>
    </collision>
    <collision>
      <origin xyz="-.084 .069 0"/>
      <geometry>
        <sphere radius="0.059"/>
      </geometry>
      <material name="redtran"/>
    </collision>
    <collision>
      <origin xyz="-.071 .057 .002"/>
      <geometry>
        <sphere radius="0.059"/>
      </geometry>
      <material name="redtran"/>
    </collision>
  </link>
  <joint name="panda_joint4" type="revolute">
    <safety_controller k_position="100.0" k_velocity="40.0" soft_lower_limit="-3.0718" soft_upper_limit="-0.0698"/>
    <origin rpy="1.57079632679 0 0" xyz="0.0825 0 0"/>
    <parent link="panda_link3"/>
    <child link="panda_link4"/>
    <axis xyz="0 0 1"/>
    <limit effort="87" lower="-3.0718" upper="-0.0698" velocity="2.1750"/>
  </joint>
  <link name="panda_link5">
    <visual>
      <geometry>
        <mesh filename="package://franka_description/meshes/visual/link5.dae"/>
      </geometry>
    </visual>
    <collision>
      <origin xyz="0 .021 -.197"/>
      <geometry>
        <sphere radius="0.053"/>
      </geometry>
      <material name="greentran"/>
    </collision>
    <collision>
      <origin xyz="-.018 .096 -.036"/>
      <geometry>
        <sphere radius="0.03"/>
      </geometry>
      <material name="greentran"/>
    </collision>
    <collision>
      <origin xyz="0 .085 0"/>
      <geometry>
        <sphere radius="0.055"/>
      </geometry>
      <material name="greentran"/>
    </collision>
    <collision>
      <origin xyz=".018 .096 -.036"/>
      <geometry>
        <sphere radius="0.03"/>
      </geometry>
      <material name="greentran"/>
    </collision>
    <collision>
      <origin xyz="0 .037 0"/>
      <geometry>
        <sphere radius="0.053"/>
      </geometry>
      <material name="greentran"/>
    </collision>
    <collision>
      <origin xyz="0 .001 -.233"/>
      <geometry>
        <sphere radius="0.062"/>
      </geometry>
      <material name="greentran"/>
    </collision>
    <collision>
      <origin xyz="0 .059 -.178"/>
      <geometry>
        <sphere radius="0.043"/>
      </geometry>
      <material name="greentran"/>
    </collision>
    <collision>
      <origin xyz=".015 .077 -.147"/>
      <geometry>
        <sphere radius="0.027"/>
      </geometry>
      <material name="greentran"/>
    </collision>
    <collision>
      <origin xyz="-.015 .091 -.076"/>
      <geometry>
        <sphere radius="0.027"/>
      </geometry>
      <material name="greentran"/>
    </collision>
    <collision>
      <origin xyz="0 .094 -.053"/>
      <geometry>
        <sphere radius="0.024"/>
      </geometry>
      <material name="greentran"/>
    </collision>
    <collision>
      <origin xyz=".015 .087 -.112"/>
      <geometry>
        <sphere radius="0.027"/>
      </geometry>
      <material name="greentran"/>
    </collision>
    <collision>
      <origin xyz="-.015 .087 -.112"/>
      <geometry>
        <sphere radius="0.027"/>
      </geometry>
      <material name="greentran"/>
    </collision>
    <collision>
      <origin xyz=".015 .091 -.076"/>
      <geometry>
        <sphere radius="0.027"/>
      </geometry>
      <material name="greentran"/>
    </collision>
    <collision>
      <origin xyz="-.015 .077 -.147"/>
      <geometry>
        <sphere radius="0.027"/>
      </geometry>
      <material name="greentran"/>
    </collision>
    <collision>
      <origin xyz="0 .081 -.132"/>
      <geometry>
        <sphere radius="0.024"/>
      </geometry>
      <material name="greentran"/>
    </collision>
    <collision>
      <origin xyz="0 .087 -.092"/>
      <geometry>
        <sphere radius="0.022"/>
      </geometry>
      <material name="greentran"/>
    </collision>
  </link>
  <joint name="panda_joint5" type="revolute">
    <safety_controller k_position="100.0" k_velocity="40.0" soft_lower_limit="-2.8973" soft_upper_limit="2.8973"/>
    <origin rpy="-1.57079632679 0 0" xyz="-0.0825 0.384 0"/>
    <parent link="panda_link4"/>
    <child link="panda_link5"/>
    <axis xyz="0 0 1"/>
    <limit effort="12" lower="-2.8973" upper="2.8973" velocity="2.6100"/>
  </joint>
  <link name="panda_link6">
    <visual>
      <geometry>
        <mesh filename="package://franka_description/meshes/visual/link6.dae"/>
      </geometry>
    </visual>
    <collision>
      <origin xyz=".087 -.03 .0"/>
      <geometry>
        <sphere radius="0.05"/>
      </geometry>
      <material name="redtran"/>
    </collision>
    <collision>
      <origin xyz=".028 .011 .009"/>
      <geometry>
        <sphere radius="0.059"/>
      </geometry>
      <material name="redtran"/>
    </collision>
    <collision>
      <origin xyz="-.001 0 .012"/>
      <geometry>
        <sphere radius="0.055"/>
      </geometry>
      <material name="redtran"/>
    </collision>
    <collision>
      <origin xyz=".079 .04 0"/>
      <geometry>
        <sphere radius="0.052"/>
      </geometry>
      <material name="redtran"/>
    </collision>
    <collision>
      <origin xyz=".09 .01 .0"/>
      <geometry>
        <sphere radius="0.049"/>
      </geometry>
      <material name="redtran"/>
    </collision>
  </link>
  <joint name="panda_joint6" type="revolute">
    <safety_controller k_position="100.0" k_velocity="40.0" soft_lower_limit="-0.0175" soft_upper_limit="3.7525"/>
    <origin rpy="1.57079632679 0 0" xyz="0 0 0"/>
    <parent link="panda_link5"/>
    <child link="panda_link6"/>
    <axis xyz="0 0 1"/>
    <limit effort="12" lower="-0.0175" upper="3.7525" velocity="2.6100"/>
  </joint>
  <link name="panda_link7">
    <visual>
      <geometry>
        <mesh filename="package://franka_description/meshes/visual/link7.dae"/>
      </geometry>
    </visual>
    <collision>
      <origin xyz=".0 .0 .075"/>
      <geometry>
        <sphere radius="0.05"/>
      </geometry>
      <material name="greentran"/>
    </collision>
    <collision>
      <origin xyz=".016 .042 .079"/>
      <geometry>
        <sphere radius="0.028"/>
      </geometry>
      <material name="greentran"/>
    </collision>
    <collision>
      <origin xyz=".041 .012 .079"/>
      <geometry>
        <sphere radius="0.028"/>
      </geometry>
      <material name="greentran"/>
    </collision>
    <collision>
      <origin xyz=".04 .058 .085"/>
      <geometry>
        <sphere radius="0.026"/>
      </geometry>
      <material name="greentran"/>
    </collision>
    <collision>
      <origin xyz=".058 .037 .083"/>
      <geometry>
        <sphere radius="0.026"/>
      </geometry>
      <material name="greentran"/>
    </collision>
  </link>
  <joint name="panda_joint7" type="revolute">
    <safety_controller k_position="100.0" k_velocity="40.0" soft_lower_limit="-2.8973" soft_upper_limit="2.8973"/>
    <origin rpy="1.57079632679 0 0" xyz="0.088 0 0"/>
    <parent link="panda_link6"/>
    <child link="panda_link7"/>
    <axis xyz="0 0 1"/>
    <limit effort="12" lower="-2.8973" upper="2.8973" velocity="2.6100"/>
  </joint>
  <link name="panda_link8"/>
  <joint name="panda_joint8" type="fixed">
    <origin rpy="0 0 0" xyz="0 0 0.107"/>
    <parent link="panda_link7"/>
    <child link="panda_link8"/>
    <axis xyz="0 0 0"/>
  </joint>
  <joint name="panda_hand_joint" type="fixed">
    <parent link="panda_link8"/>
    <child link="panda_hand"/>
    <origin rpy="0 0 -0.785398163397" xyz="0 0 0"/>
  </joint>
  <link name="panda_hand">
    <visual>
      <geometry>
        <mesh filename="package://franka_description/meshes/visual/hand.dae"/>
      </geometry>
    </visual>
    <collision>
      <origin xyz="0 -.077 .041"/>
      <geometry>
        <sphere radius="0.033"/>
      </geometry>
      <material name="redtran"/>
    </collision>
    <collision>
      <origin xyz="0 .075 .012"/>
      <geometry>
        <sphere radius="0.033"/>
      </geometry>
      <material name="redtran"/>
    </collision>
    <collision>
      <origin xyz="0 .077 .041"/>
      <geometry>
        <sphere radius="0.033"/>
      </geometry>
      <material name="redtran"/>
    </collision>
    <collision>
      <origin xyz="0 -.05 .002"/>
      <geometry>
        <sphere radius="0.033"/>
      </geometry>
      <material name="redtran"/>
    </collision>
    <collision>
      <origin xyz="0 -.046 .041"/>
      <geometry>
        <sphere radius="0.033"/>
      </geometry>
      <material name="redtran"/>
    </collision>
    <collision>
      <origin xyz="0 .046 .041"/>
      <geometry>
        <sphere radius="0.033"/>
      </geometry>
      <material name="redtran"/>
    </collision>
    <collision>
      <origin xyz="0 .016 .041"/>
      <geometry>
        <sphere radius="0.033"/>
      </geometry>
      <material name="redtran"/>
    </collision>
    <collision>
      <origin xyz="0 -.016 .041"/>
      <geometry>
        <sphere radius="0.033"/>
      </geometry>
      <material name="redtran"/>
    </collision>
    <collision>
      <origin xyz="0 -.075 .002"/>
      <geometry>
        <sphere radius="0.033"/>
      </geometry>
      <material name="redtran"/>
    </collision>
    <collision>
      <origin xyz="0 .051 .003"/>
      <geometry>
        <sphere radius="0.033"/>
      </geometry>
      <material name="redtran"/>
    </collision>
    <collision>
      <origin xyz="0 0 .003"/>
      <geometry>
        <sphere radius="0.033"/>
      </geometry>
      <material name="redtran"/>
    </collision>
  </link>
  <link name="panda_leftfinger">
    <visual>
      <geometry>
        <mesh filename="package://franka_description/meshes/visual/finger.dae"/>
      </geometry>
    </visual>
    <collision>
      <origin xyz="0 .014 .022"/>
      <geometry>
        <sphere radius="0.017"/>
      </geometry>
      <material name="greentran"/>
    </collision>
    <collision>
      <origin xyz="0 .015 .005"/>
      <geometry>
        <sphere radius="0.018"/>
      </geometry>
      <material name="greentran"/>
    </collision>
    <collision>
      <origin xyz="0 .008 .044"/>
      <geometry>
        <sphere radius="0.014"/>
      </geometry>
      <material name="greentran"/>
    </collision>
  </link>
  <link name="panda_rightfinger">
    <visual>
      <origin rpy="0 0 3.14159265359" xyz="0 0 0"/>
      <geometry>
        <mesh filename="package://franka_description/meshes/visual/finger.dae"/>
      </geometry>
    </visual>
    <collision>
      <origin xyz="0 -.014 .022"/>
      <geometry>
        <sphere radius="0.017"/>
      </geometry>
      <material name="greentran"/>
    </collision>
    <collision>
      <origin xyz="0 -.015 .005"/>
      <geometry>
        <sphere radius="0.018"/>
      </geometry>
      <material name="greentran"/>
    </collision>
    <collision>
      <origin xyz="0 -.008 .044"/>
      <geometry>
        <sphere radius="0.014"/>
      </geometry>
      <material name="greentran"/>
    </collision>
  </link>
  <link name="panda_hand_center"/>
  <joint name="panda_finger_joint1" type="fixed">
    <parent link="panda_hand"/>
    <child link="panda_leftfinger"/>
    <origin rpy="0 0 0" xyz="0 0.02 0.0584"/>
  </joint>
  <joint name="panda_finger_joint2" type="fixed">
    <parent link="panda_hand"/>
    <child link="panda_rightfinger"/>
    <origin rpy="0 0 0" xyz="0 -0.02 0.0584"/>
    <mimic joint="panda_finger_joint1"/>
  </joint>
  <joint name="panda_hand_center_joint" type="fixed">
    <parent link="panda_hand"/>
    <child link="panda_hand_center"/>
    <origin rpy="0 0 0" xyz="0 0 0.08"/>
  </joint>
  <joint name="mug_joint" type="floating">
    <parent link="table"/>
    <child link="mug"/>
    <origin rpy="0 0 0" xyz="0 0 0"/>
  </joint>
  <link name="mug">
    <visual>
      <geometry>
        <mesh filename="package://franka_pbds_controllers/meshes/mug.dae"/>
      </geometry>
    </visual>
  </link>
  <link name="mug_rim_center"/>
  <joint name="mug_rim_center_joint" type="fixed">
    <parent link="mug"/>
    <child link="mug_rim_center"/>
    <origin rpy="0 0 0" xyz="0 0 0.105"/>
  </joint>
</robot>

